<?xml version="1.0" encoding="UTF-8"?>
<!-- Generated by org.testng.reporters.JUnitXMLReporter -->
<testsuite ignored="0" hostname="DESKTOP-DO7M1Q3" failures="1" tests="3" name="Default test" time="25.585" errors="0" timestamp="2022-03-01T16:58:36 IST">
  <testcase classname="io.cucumber.testng.AbstractTestNGCucumberTests" name="runScenario" time="21.059"/>
  <testcase classname="io.cucumber.testng.AbstractTestNGCucumberTests" name="runScenario" time="21.048"/>
  <testcase classname="io.cucumber.testng.AbstractTestNGCucumberTests" name="runScenario" time="21.104">
    <failure type="java.lang.AssertionError" message="expected [validation failed1] but found [validation failed]">
      <![CDATA[java.lang.AssertionError: expected [validation failed1] but found [validation failed]
at org.testng.Assert.fail(Assert.java:99)
at org.testng.Assert.failNotEquals(Assert.java:1037)
at org.testng.Assert.assertEqualsImpl(Assert.java:140)
at org.testng.Assert.assertEquals(Assert.java:122)
at org.testng.Assert.assertEquals(Assert.java:629)
at org.testng.Assert.assertEquals(Assert.java:639)
at stepsDefinitions.LoginSteps.i_should_get_validation_alert_with(LoginSteps.java:43)
at âœ½.I should get validation alert with  "validation failed1"(classpath:features/login.feature:11)
]]>
    </failure>
  </testcase> <!-- runScenario -->
</testsuite> <!-- Default test -->
